Workbook

Sheet Summary
A1: SPINE run-2 scorecard: astropy__astropy-12907. STATUS: FINAL, revised 2026-08-08 per the 2026-08-04 meeting precision ruling (Open_rulings #12). All 12 rulings resolved.
A2: Three settings x two models, one shared prompt prefix, tails differ. Coverage means named, not succeeded. Manual scoring is authoritative; mechanical values are a reproducibility layer.
A4: Metric | B4: CLAUDE unstr | C4: CLAUDE traj | D4: CLAUDE struct | E4: GPT unstr | F4: GPT traj | G4: GPT struct | H4: Basis
A5: Recall | B5: =IF(COUNT(Coverage!C6:C11)=6,AVERAGE(Coverage!C6:C11),"PENDING") -> 0.58333333 | C5: =IF(COUNT(Coverage!D6:D11)=6,AVERAGE(Coverage!D6:D11),"PENDING") -> 0.75 | D5: =IF(COUNT(Coverage!E6:E11)=6,AVERAGE(Coverage!E6:E11),"PENDING") -> 1 | E5: =IF(COUNT(Coverage!F6:F11)=6,AVERAGE(Coverage!F6:F11),"PENDING") -> 1 | F5: =IF(COUNT(Coverage!G6:G11)=6,AVERAGE(Coverage!G6:G11),"PENDING") -> 0.91666667 | G5: =IF(COUNT(Coverage!H6:H11)=6,AVERAGE(Coverage!H6:H11),"PENDING") -> 1 | H5: mean of Coverage rows; PENDING until all six GT rows are scored
A6: Precision | B6: =IF(COUNT(Precision_unstr!C5:C16)>0,ROUND(AVERAGE(Precision_unstr!C5:C16),2),"PENDING") -> 1 | C6: =IF(COUNT(Precision_traj!E5:E38)>0,ROUND(AVERAGE(Precision_traj!E5:E38),2),"PENDING") -> 1 | D6: =IF(COUNT(Precision_struct!C6:C15)>0,ROUND(AVERAGE(Precision_struct!C6:C15),2),"PENDING") -> 1 | E6: =IF(COUNT(Precision_unstr!H5:H11)>0,ROUND(AVERAGE(Precision_unstr!H5:H11),2),"PENDING") -> 1 | F6: =IF(COUNT(Precision_traj!E42:E49)>0,ROUND(AVERAGE(Precision_traj!E42:E49),2),"PENDING") -> 1 | G6: =IF(COUNT(Precision_struct!H6:H13)>0,ROUND(AVERAGE(Precision_struct!H6:H13),2),"PENDING") -> 1 | H6: mean of rel over kept units, root excluded; revised 2026-08-08 per meeting ruling R1 (Open_rulings #12)
A7: TC | B7: =Recoverability!D5 -> 0 | C7: =Recoverability!D6 -> 0 | D7: =Recoverability!D7 -> 1 | E7: =Recoverability!D8 -> 0 | F7: =Recoverability!D9 -> 0 | G7: =Recoverability!D10 -> 1 | H7: Recoverability, per-node rule
A8: AC | B8: =Recoverability!E5 -> 0 | C8: =Recoverability!E6 -> 0 | D8: =Recoverability!E7 -> 1 | E8: =Recoverability!E8 -> 0 | F8: =Recoverability!E9 -> 0 | G8: =Recoverability!E10 -> 1 | H8: Recoverability, definer resolves to a responsible authority
A9: EF | B9: =Recoverability!F5 -> 0 | C9: =Recoverability!F6 -> 1 | D9: =Recoverability!F7 -> 1 | E9: =Recoverability!F8 -> 0 | F9: =Recoverability!F9 -> 1 | G9: =Recoverability!F10 -> 1 | H9: Recoverability; trajectory cells open ruling
A10: SIF | B10: =SIF!B10 -> 0.3 | C10: =SIF!C10 -> 0.3 | D10: =SIF!D10 -> 0.9 | E10: =SIF!E10 -> 0.3 | F10: =SIF!F10 -> 0.3 | G10: =SIF!G10 -> 0.9 | H10: SIF sheet mean of 5 elements

Sheet Coverage
A1: Recall: which of the 6 answer-key obligations does each artifact name. Coverage means named, not succeeded.
A2: Scale: 1 = covered, 0.5 = gestured at without specifics, 0 = absent. Fill the YELLOW cells. Manual scoring is authoritative.
A3: EXAMPLE of a filled row (format only, not data): GT-0x | obligation text | 1 | 0.5 | 0 | 1 | 1 | 1 | short basis note
A5: GT id | B5: Obligation | C5: CLAUDE unstr | D5: CLAUDE traj | E5: CLAUDE struct | F5: GPT unstr | G5: GPT traj | H5: GPT struct | I5: Notes
A6: GT-01 | B6: Reproduce the reported incorrect behavior | C6: 0 | D6: 0 | E6: 1 | F6: 1 | G6: 0.5 | H6: 1 | I6: Traj cells: four-tool vocabulary has no run capability; run-1 disclosed confound carries over.
A7: GT-02 | B7: Localize the defect in the separability computation | C7: 1 | D7: 1 | E7: 1 | F7: 1 | G7: 1 | H7: 1
A8: GT-03 | B8: Characterize why nesting specifically breaks it | C8: 1 | D8: 1 | E8: 1 | F8: 1 | G8: 1 | H8: 1
A9: GT-04 | B9: Correct the computation for nested CompoundModels | C9: 1 | D9: 1 | E9: 1 | F9: 1 | G9: 1 | H9: 1 | I9: Claude traj: zero edit_file among 34 actions (16 search, 17 open, 1 done). Ruling needed whether an edit described only in thought text counts.
A10: GT-05 | B10: Verify the reported case yields the expected output | C10: 0.5 | D10: 1 | E10: 1 | F10: 1 | G10: 1 | H10: 1
A11: GT-06 | B11: Preserve existing behavior (no regressions) | C11: 0 | D11: 0.5 | E11: 1 | F11: 1 | G11: 1 | H11: 1

Sheet Precision_struct
A1: Precision: is each emitted policy inside the intent. 1 = relevant, 0 = beyond-intent. Root P0 excluded (restates the intent).
A2: Fill/confirm the rel cells. Meeting ruling 2026-08-04 (R1): beyond-intent-but-correct steps are not penalized; run-1 rulings #2 (new-test authoring) and #3 (delivery/report class) are superseded, both classes now rel 1. Run-1 ruling #6 (monitor = 1) unchanged. The run-2 reproduction-vehicle carve-out is retained and subsumed by R1.
A4: CLAUDE id | B4: level | action / resource | rationale | C4: rel | D4: note | F4: GPT id | G4: level | action / resource | rationale | H4: rel | I4: note
A5: P0 | B5: decl | fix / separability_matrix function in astropy.modeling.separable | Restates the raw intent: the separability_matrix function must correct | D5: ROOT EXCLUDED from precision | F5: P0 | G5: decl | resolve / Astropy modeling separability computation for nested Compoun | Restates the reported goal of making nested CompoundModel separability | I5: ROOT EXCLUDED from precision
A6: P1 | B6: defi | monitor / separability_matrix output for nested CompoundModel inputs | To fix the bug we must first observe the incorrect behavior: monitor t | C6: 1 | F6: P1 | G6: defi | reproduce / ['the nested expression `Pix2Sky_TAN() & (Linear1D(10) & Lin | A correction requires a stable reproduction showing that nesting chang | H6: 1
A7: P2 | B7: defi | analyze / separability_matrix internal logic for CompoundModel recursi | Understanding the root cause requires analyzing how separability_matri | C7: 1 | F7: P2 | G7: defi | trace / ['`separability_matrix`', 'recursive separability helper fun | The discrepancy must be traced through recursive handling of nested co | H7: 1
A8: P2.1 | B8: defi | identify / _separable and _cstack helper functions in astropy.modeling. | The bug likely resides in the helper functions (_separable, _cstack, o | C8: 1 | F8: P3 | G8: defi | derive / ['expected separability matrix for nested parallel compositi | The implementation should be guided by the established dependency sema | H8: 1
A9: P2.2 | B9: defi | compare / separability_matrix results for flat vs. nested equivalent C | Comparing the matrix produced by the flat form (Pix2Sky_TAN() & Linear | C9: 1 | F9: P4 | G9: impe | add / ['regression test for `Pix2Sky_TAN() & (Linear1D(10) & Linea | A regression test preserves the reproduced failure and defines the req | H9: 1 | I9: carve-out: authored as the reproduction vehicle, counts as reproduction
A10: P3 | B10: defi | decide / separability_matrix recursion logic for nested CompoundModel | Once the defective code path is identified, a repair plan must be deci | C10: 1 | F10: P5 | G10: defi | select / the minimal separability-composition correction that preserv | After locating the faulty recursive composition behavior, a minimal co | H10: 1
A11: P3.1 | B11: defi | design / corrected block-diagonal combination rule for '&' operator i | The fix must ensure that when a CompoundModel operand joined by '&' is | C11: 1 | F11: P6 | G11: impe | modify / the nested parallel-composition separability logic so it com | Preserving the recursive child matrices during `&` composition directl | H11: 1
A12: P3.2 | B12: defi | design / regression test cases for separability_matrix with nested Co | A test plan must be designed covering: flat compound models, singly-ne | C12: 1 | D12: R1 (2026-08-04 meeting): beyond-intent-but-correct is not penalized; supersedes run-1 ruling #2. Was 0. | F12: P7 | G12: impe | run / ['new nested CompoundModel separability regression tests', ' | Running focused and related tests verifies that the correction fixes n | H12: 1
A13: P4 | B13: impe | patch / _separable function (or equivalent combiner) in astropy/mode | Directly modify the code path that handles the '&' (join/concatenate) | C13: 1 | F13: P8 | G13: impe | report / ['test outcomes', 'before-and-after separability matrices', | Recording the diagnosis and validation results provides an auditable p | H13: 1 | I13: R1 (2026-08-04 meeting): beyond-intent-but-correct is not penalized; supersedes run-1 ruling #3 and run-2 ruling #9. Was 0.
A14: P5 | B14: impe | add / unit tests asserting correct separability matrices for neste | Add concrete test cases (e.g., separability_matrix(Pix2Sky_TAN() & (Li | C14: 1 | D14: R1 (2026-08-04 meeting): beyond-intent-but-correct is not penalized; supersedes run-1 ruling #2. Was 0.
A15: P6 | B15: impe | validate / full astropy.modeling test suite output | After patching, run the full modeling test suite to confirm no existin | C15: 1

Sheet Precision_unstr
A1: Precision, unstructured cells. Unit = one asserted step; the candidate list below is a mechanical extraction of the response headings.
A2: First adjudicate the unit list itself (merge, split, strike), then fill the YELLOW rel cells for the units kept.
A4: CLAUDE item | B4: heading | C4: rel | D4: note | F4: GPT item | G4: heading | H4: rel | I4: note
A5: U1 | B5: Analysis of the Problem | D5: struck: heading or container, not an asserted step | F5: U1 | G5: Plan to resolve the nested `CompoundModel` separability issue | I5: struck: title, not an asserted step
A6: U2 | B6: Investigation Plan | D6: struck: heading or container, not an asserted step | F6: U2 | G6: 1. Reproduce the failure with the reported examples | H6: 1
A7: U3 | B7: Understand the Code Structure | C7: 1 | F7: U3 | G7: 2. Trace the separability recursion for the `&` operator | H7: 1
A8: U4 | B8: Trace the Bug | C8: 1 | F8: U4 | G8: 3. Identify the matrix-preservation bug | H8: 1
A9: U5 | B9: Identify the Bug | C9: 1 | F9: U5 | G9: 4. Make the minimal implementation correction | H9: 1
A10: U6 | B10: Look at `_cstack` Implementation | C10: 1 | F10: U6 | G10: 5. Add regression tests | H10: 1 | I10: R1 (2026-08-04 meeting): beyond-intent-but-correct is not penalized; supersedes run-1 ruling #2. Was 0.
A11: U7 | B11: The Fix | C11: 1 | F11: U7 | G11: 6. Run the relevant modeling test suite | H11: 1
A12: U8 | B12: Concrete Fix Plan | D12: struck: heading or container, not an asserted step
A13: U9 | B13: 1. Locate | C13: 1 | D13: duplicate of the investigation steps; kept, duplication is not beyond-intent
A14: U10 | B14: 2. Find | C14: 1 | D14: duplicate of the investigation steps; kept, duplication is not beyond-intent
A15: U11 | B15: 3. Identify | C15: 1 | D15: duplicate of the investigation steps; kept, duplication is not beyond-intent
A16: U12 | B16: 4. Fix | C16: 1 | D16: duplicate of the investigation steps; kept, duplication is not beyond-intent

Sheet Precision_traj
A1: Precision, trajectory cells. Unit = one step (mechanical transcription from parsed_steps). Fill the YELLOW rel cells.
A2: All 42 steps are on-intent, rel=1 throughout; no unit falls in the run-1 beyond-intent classes. Redundancy (mechanical, observation only, not a precision input): CLAUDE 30 unique operations of 34 (one open repeated x3, two slices x2), GPT 7 of 8. GT step 6 authors the failing test; kept rel 1 under the reproduction-vehicle carve-out.
A3: CLAUDE trajectory (34 steps)
A4: step | B4: action | C4: args | D4: thought (first 70 chars) | E4: rel | F4: note
A5: 1 | B5: open_file | C5: {"path": "astropy/modeling/separable.py"} | D5: First, let me look at the separable.py file which contains the separab | E5: 1
A6: 2 | B6: search_repo | C6: {"query": "_cstack _cdot separable compound"} | D6: Now I need to understand the _separable function and how it handles Co | E6: 1
A7: 3 | B7: search_repo | C7: {"query": "def _separable"} | D7: Let me look more carefully at the _separable function to understand ho | E7: 1
A8: 4 | B8: open_file | C8: {"path": "astropy/modeling/separable.py"} | D8: Let me look at the full separable.py file content to understand the co | E8: 1
A9: 5 | B9: search_repo | C9: {"query": "def _separable separability_matrix | D9: Based on my reading of the code, I need to understand the issue. The ` | E9: 1
A10: 6 | B10: open_file | C10: {"path": "astropy/modeling/separable.py", "st | D10: Let me open the separable.py file and look at specific line ranges to | E10: 1
A11: 7 | B11: open_file | C11: {"path": "astropy/modeling/separable.py", "st | D11: Let me look at more of the file to find the _separable function. | E11: 1
A12: 8 | B12: open_file | C12: {"path": "astropy/modeling/separable.py", "st | D12: Let me look at more of the file. | E12: 1
A13: 9 | B13: open_file | C13: {"path": "astropy/modeling/separable.py", "st | D13: Now I have a good understanding of the code. Let me analyze the bug: | E13: 1
A14: 10 | B14: search_repo | C14: {"query": "def _cstack"} | D14: Now I understand the issue. Let me look at the `_cstack` function to u | E14: 1
A15: 11 | B15: open_file | C15: {"path": "astropy/modeling/separable.py", "st | D15: Based on my analysis, I now understand the bug. In the `_separable` fu | E15: 1
A16: 12 | B16: search_repo | C16: {"query": "_cstack _cdot _coord_matrix"} | D16: Now I have a complete picture. Let me trace through the code to find t | E16: 1
... A20: 16 | B20: open_file | C20: {"path": "astropy/modeling/separable.py", "st | D20: Based on my analysis so far, I believe the bug is in the `_separable` | E20: 1
A21: 17 | B21: search_repo | C21: {"query": "CompoundModel separable _separable | D21: Let me try a different approach and search for the key parts of the co | E21: 1 | F21: retry admission in thought
A22: 18 | B22: search_repo | C22: {"query": "def separability_matrix def _separ | D22: Let me look at the full separable.py file by searching for specific fu | E22: 1
A23: 19 | B23: open_file | C23: {"path": "astropy/modeling/separable.py", "st | D23: Let me try to open the file with a broader range to see all the conten | E23: 1
A24: 20 | B24: open_file | C24: {"path": "astropy/modeling/separable.py", "st | D24: Based on my analysis, I now have a clear understanding of the bug. Let | E24: 1
A25: 21 | B25: search_repo | C25: {"query": "isinstance CompoundModel _coord_ma | D25: I need to see the actual file. Let me try a search to find the key lin | E25: 1
A26: 22 | B26: open_file | C26: {"path": "astropy/modeling/separable.py"} | D26: Let me look at the file structure to understand what's in separable.py | E26: 1
A27: 23 | B27: open_file | C27: {"path": "astropy/modeling/separable.py", "st | D27: Based on my extensive analysis, I'm confident about the bug location a | E27: 1
A28: 24 | B28: search_repo | C28: {"query": "cstack cdot _coord_matrix left_coo | D28: I've been trying to open the file multiple times. Let me try a differe | E28: 1 | F28: thought: I've been trying to open the file multiple times
A29: 25 | B29: search_repo | C29: {"query": "_coord_matrix model axes"} | D29: Let me try to find the exact location of the bug by searching for the | E29: 1
A30: 26 | B30: search_repo | C30: {"query": "separability_matrix compound_model | D30: Let me try to look at the file using a search for specific text. | E30: 1
A31: 27 | B31: search_repo | C31: {"query": "file:separable.py _separable"} | D31: Let me try to find the file by looking at the directory structure. | E31: 1
A32: 28 | B32: open_file | C32: {"path": "astropy/modeling/separable.py", "st | D32: Based on all my analysis, I'm now confident about the bug and the fix. | E32: 1
A33: 29 | B33: search_repo | C33: {"query": "def _separable transform"} | D33: I keep getting the same result. Let me try to look at the file differe | E33: 1 | F33: thought: I keep getting the same result
A34: 30 | B34: search_repo | C34: {"query": "test_separability separability_mat | D34: Let me try to find the exact code by looking at the git history or tes | E34: 1
A35: 31 | B35: open_file | C35: {"path": "astropy/modeling/tests/test_separab | D35: Let me look at the test file for separability to understand the expect | E35: 1
A36: 32 | B36: open_file | C36: {"path": "astropy/modeling/separable.py", "st | D36: Now I have a clear picture. Based on my analysis, the bug is in the `_ | E36: 1
A37: 33 | B37: search_repo | C37: {"query": "noutp nout left right _cstack _cdo | D37: I've been unable to see the file content through the open_file tool. L | E37: 1 | F37: thought: unable to see the file content
A38: 34 | B38: done | C38: {"summary": "## Plan for Resolving the Separa | D38: Based on all my research, I now have a comprehensive understanding of | E38: 1
A40: GPT trajectory (8 steps)
A41: step | B41: action | C41: args | D41: thought (first 70 chars) | E41: rel | F41: note
A42: 1 | B42: search_repo | C42: {"query": "separability_matrix _cstack separa | D42: Locate the separability implementation and its existing regression tes | E42: 1
A43: 2 | B43: open_file | C43: {"path": "astropy/modeling/separable.py"} | D43: Inspect the public `separability_matrix` entry point and the recursive | E43: 1
A44: 3 | B44: search_repo | C44: {"query": "separability_matrix(", "path": "as | D44: Examine the tests nearest to the implementation so the intended semant | E44: 1
...

Sheet Recoverability
A1: TC / AC / EF across the six artifacts. Structural only, never content quality. Values below are PROPOSED; confirm or overrule each row.
A2: Per-node rule (run-1, locked): lineage must be retrievable per node for TC credit. Definer must resolve to a responsible authority for AC.
A4: Artifact | B4: modality | C4: nodes / steps | D4: TC | E4: AC | F4: EF | G4: basis
A5: CLAUDE plan_unstructured | B5: plan | C5: prose | D5: 0 | E5: 0 | F5: 0 | G5: proposed: no per-node lineage, definer, or anchored rationale fields exist; probe all zero. Reasoning present as prose only.
A6: CLAUDE plan_trajectory | B6: plan | C6: 34 steps | D6: 0 | E6: 0 | F6: 1 | G6: TC/AC 0 proposed: no parent or definer on any step (mechanical). EF 1.00 per run-1 precedent: every step carries a thought, so rationale is recoverable as a field; narrowing stated, lineage separation is carried by TC/AC, not EF. Ruling 1 resolved.
A7: CLAUDE plan_structured | B7: plan | C7: 11 policies | D7: 1 | E7: 1 | F7: 1 | G7: mechanical, verified: 11/11 carry parent_id resolving to P0, definer by level, rationale present. Confirm.
A8: GPT plan_unstructured | B8: plan | C8: prose | D8: 0 | E8: 0 | F8: 0 | G8: proposed: same basis as Claude unstructured; probe all zero.
A9: GPT plan_trajectory | B9: plan | C9: 8 steps | D9: 0 | E9: 0 | F9: 1 | G9: TC/AC 0 proposed: no parent or definer on any step (mechanical). EF 1.00 per run-1 precedent: every step carries a thought, so rationale is recoverable as a field; narrowing stated, lineage separation is carried by TC/AC, not EF. Ruling 1 resolved.
A10: GPT plan_structured | B10: plan | C10: 9 policies | D10: 1 | E10: 1 | F10: 1 | G10: mechanical, verified: 9/9 parent_id resolve, definer by level, rationale present. Confirm.

Sheet SIF
A1: Semantic Intent Fidelity: 5 root-tuple elements, scored once at intent level. 0 / 0.5 / 1 partial credit. Fill the YELLOW cells.
A2: Evidence transcriptions are in SIF_detail. Spatial is the probe cell from run 1: stated whole vs reassembled.
A4: Element | B4: CLAUDE unstr | C4: CLAUDE traj | D4: CLAUDE struct | E4: GPT unstr | F4: GPT traj | G4: GPT struct | H4: Notes
A5: Action | B5: 0.5 | C5: 0.5 | D5: 1 | E5: 0.5 | F5: 0.5 | G5: 1 | H5: prose cells capped at 0.5 per run-1 not-a-field convention (ruling 8)
A6: Resource | B6: 0.5 | C6: 0.5 | D6: 0.5 | E6: 0.5 | F6: 0.5 | G6: 1
A7: Spatial | B7: 0.5 | C7: 0.5 | D7: 1 | E7: 0.5 | F7: 0.5 | G7: 1
A8: Temporal | B8: 0 | C8: 0 | D8: 1 | E8: 0 | F8: 0 | G8: 1
A9: Context | B9: 0 | C9: 0 | D9: 1 | E9: 0 | F9: 0 | G9: 0.5
A10: SIF (mean) | B10: =IF(COUNT(B5:B9)=5,AVERAGE(B5:B9),"PENDING") -> 0.3 | C10: =IF(COUNT(C5:C9)=5,AVERAGE(C5:C9),"PENDING") -> 0.3 | D10: =IF(COUNT(D5:D9)=5,AVERAGE(D5:D9),"PENDING") -> 0.9 | E10: =IF(COUNT(E5:E9)=5,AVERAGE(E5:E9),"PENDING") -> 0.3 | F10: =IF(COUNT(F5:F9)=5,AVERAGE(F5:F9),"PENDING") -> 0.3 | G10: =IF(COUNT(G5:G9)=5,AVERAGE(G5:G9),"PENDING") -> 0.9

Sheet SIF_detail
A1: SIF evidence. Structured columns transcribed mechanically from each P0. Unstructured / trajectory evidence columns are yours to fill from the responses.
A3: Element | B3: GT reference (P0) | C3: CLAUDE struct P0 field | D3: GPT struct P0 field | E3: CLAUDE unstr / traj: where it appears | F3: GPT unstr / traj: where it appears
A4: Action | B4: fix | C4: fix | D4: resolve | E4: CU: Concrete Fix Plan / CT: ### Fix in done summary | F4: GU: Plan to resolve / GT: minimal implementation correction
A5: Resource | B5: separability computation for nested CompoundModels | C5: separability_matrix function in astropy.modeling.separable [nested appears in five child resource fields: P1, P2.2, P3, P3.2, P5; refined downward, not lost; 0.5 per the reassembly tier] | D5: Astropy modeling separability computation for nested CompoundModel expressions | E5: CU+CT: nested CompoundModels separability named in prose | F5: GU: nested CompoundModel separability / GT: nested compound models
A6: Spatial | B6: astropy repository | C6: astropy.modeling.separable module | D6: repository modeling package | E6: CU: separable.py in prose / CT: path in tool args | F6: GU: astropy.modeling in prose / GT: path in tool args
A7: Temporal | B7: always | C7: always | D7: always | E7: absent in both | F7: absent in both
A8: Context | B8: production | C8: production | D8: repository maintenance | E8: absent in both | F8: absent in both

Sheet Evidence
A1: Evidence: every proposed score with its basis and a Ctrl-F anchor. Anchors are verbatim substrings of the artifact response_text (or an absence check with term counts), machine-verified at build time.
A2: Open the artifact json (or its .readable.txt companion) and Ctrl-F the anchor. Absence anchors: Ctrl-F the term and confirm zero hits.
A4: Cell | B4: Artifact file | C4: Proposed | D4: Basis | E4: Ctrl-F anchor | F4: Verified
A5: Coverage GT-01 CU | B5: plan_unstructured_astropy__astropy-12907_claude-sonnet-4-6_run1.json | C5: 0 | D5: no reproduction or test step anywhere; the plan is analysis-only | E5: [absence: reproduce=0, test=0] | F5: yes
A6: Coverage GT-02 CU | B6: plan_unstructured_astropy__astropy-12907_claude-sonnet-4-6_run1.json | C6: 1 | D6: names file and helper functions | E6: `astropy/modeling/separable.py` - the main file | F6: yes
A7: Coverage GT-03 CU | B7: plan_unstructured_astropy__astropy-12907_claude-sonnet-4-6_run1.json | C7: 1 | D7: explains the nested-specific failure mode | E7: the case where the right operand is itself | F7: yes
A8: Coverage GT-04 CU | B8: plan_unstructured_astropy__astropy-12907_claude-sonnet-4-6_run1.json | C8: 1 | D8: fix step targets _cstack block construction | E8: correctly build the block diagonal matrix from the two input separability matrices | F8: yes
A9: Coverage GT-05 CU | B9: plan_unstructured_astropy__astropy-12907_claude-sonnet-4-6_run1.json | C9: 0.5 | D9: expected matrix named analytically; no post-fix verification step | E9: should produce a 4 | F9: yes
A10: Coverage GT-06 CU | B10: plan_unstructured_astropy__astropy-12907_claude-sonnet-4-6_run1.json | C10: 0 | D10: no regression or existing-suite mention | E10: [absence: regress=0, existing=0] | F10: yes
A11: Coverage GT-01 CT | B11: plan_trajectory_astropy__astropy-12907_claude-sonnet-4-6_run1.json | C11: 0 | D11: no reproduction named; four-tool vocabulary also cannot run (run-1 confound) | E11: [absence: reproduce=0] | F11: yes
A12: Coverage GT-02 CT | B12: plan_trajectory_astropy__astropy-12907_claude-sonnet-4-6_run1.json | C12: 1 | D12: localizes to file and function | E12: The bug is in `astropy/modeling/separable.py` in the `_separable` function | F12: yes
A13: Coverage GT-03 CT | B13: plan_trajectory_astropy__astropy-12907_claude-sonnet-4-6_run1.json | C13: 1 | D13: characterizes: _coord_matrix flattens a nested compound to all-True | E13: incorrectly creates a 2x2 all-True matrix instead of the correct 2x2 diagonal | F13: yes
A14: Coverage GT-04 CT | B14: plan_trajectory_astropy__astropy-12907_claude-sonnet-4-6_run1.json | C14: 1 | D14: done summary names the modify step with a concrete code sketch; NOTE zero edit_file actions (ruling 2) | E14: to check if sub-models are CompoundModels | F14: yes
A15: Coverage GT-05 CT | B15: plan_trajectory_astropy__astropy-12907_claude-sonnet-4-6_run1.json | C15: 1 | D15: verify step with the reported example and expected matrix | E15: by running the example from the issue | F15: yes
A16: Coverage GT-06 CT | B16: plan_trajectory_astropy__astropy-12907_claude-sonnet-4-6_run1.json | C16: 0.5 | D16: regression prevention via new tests is named; running the existing suite is not | E16: to prevent regression | F16: yes
... A79: Precision GT step 6 | B79: plan_trajectory GPT | C79: 1 | D79: carve-out: reproduction-vehicle test authoring | E79: This test should fail before the implementation correct | F79: yes
A80: Redundancy CT and GT | B80: trajectory artifacts | C80: 0.88 / 0.88 | D80: mechanical observation, not a precision input: unique operations over total, CLAUDE 30/34, GPT 7/8 | E80: "open_file": 17 | F80: yes

Sheet Overhead
A1: Overhead: audit traversal O(depth) processing time plus storage bytes. Locked cross-domain convention.
A2: Bytes convention for run 2: len of json.dumps(parsed_tree, indent=2), stated here as the assumption. Times come from measure_overhead.py; fill the YELLOW cells after running it.
A4: Artifact | B4: nodes | C4: depth | D4: bytes | E4: B/node | F4: time (us) | G4: note
A5: CLAUDE tree (11) | B5: 11 | C5: 5 | D5: 8615 | E5: =ROUND(D5/B5,0) -> 783 | F5: 0.35 | G5: pointer walk, deepest leaf to P0; time measured on the governing machine
A6: GPT tree (9) | B6: 9 | C6: 6 | D6: 6559 | E6: =ROUND(D6/B6,0) -> 729 | F6: 0.41 | G6: pointer walk, deepest leaf to P0; time measured on the governing machine
A8: O(n) baseline: full-text scan of the flat artifacts, same machine
A9: Artifact | B9: chars | D9: file B | F9: time (us)
A10: CLAUDE prose | B10: 4110 | D10: 8038 | F10: 12.91
A11: GPT prose | B11: 3224 | D11: 7119 | F11: 9.51
A12: CLAUDE traj | B12: 24895 | D12: 56937 | F12: 75.21
A13: GPT traj | B13: 5684 | D13: 16683 | F13: 12.16
A15: Reading: traversal is O(depth) over the lineage chain (0.35 and 0.41 us at depths 5 and 6); reconstruction over a flat artifact is O(n) over its full text (9.51 to 75.21 us here, growing with artifact length). Measured with review_tools/measure_overhead.py; the governing machine's numbers are recorded, container smoke-test values are not.

Sheet Run_integrity
A1: Run integrity, mechanical, prefilled. Every value is read from the artifact json.
A3: Artifact | B3: model | C3: outcome | D3: tok in | E3: tok out | F3: cap | G3: wall s | H3: prompt/request sha16 | I3: parse | J3: recomputed
A4: CLAUDE plan_unstructured | B4: claude-sonnet-4-6 | C4: completed | D4: 433 | E4: 1164 | F4: 8000 | G4: 21.82 | H4: 76a601f1f3ee38ca | I4: none | J4: n/a
A5: CLAUDE plan_trajectory | B5: claude-sonnet-4-6 | C5: completed | D5: 548 | E5: 7451 | F5: 8000 | G5: 96.04 | H5: 08aaa6457fa034af | I5: none | J5: True
A6: CLAUDE plan_structured | B6: claude-sonnet-4-6 | C6: completed | D6: 2676 | E6: 2453 | F6: 8000 | G6: 32.18 | H6: e525bb7aba487577 | I6: none | J6: True
A7: GPT plan_unstructured | B7: gpt-5.6-terra | C7: completed | D7: 381 | E7: 1330 | F7: 16000 | G7: 13.88 | H7: 76a601f1f3ee38ca | I7: none | J7: n/a
A8: GPT plan_trajectory | B8: gpt-5.6-terra | C8: completed | D8: 485 | E8: 1257 | F8: 8000 | G8: 11.74 | H8: 08aaa6457fa034af | I8: none | J8: True
A9: GPT plan_structured | B9: gpt-5.6-terra | C9: completed | D9: 2407 | E9: 1838 | F9: 8000 | G9: 16.25 | H9: e525bb7aba487577 | I9: none | J9: True

Sheet Disclosures
A1: Disclosures and ledger. Facts and status only.
A3: Instrument v2 boundary | B3: One shared generic prefix (sha16 565d11bb0247d609) plus three tails: none / trajectory format / policy grammar. Prompt sha16: unstructured 76a601f1f3ee38ca, trajectory 08aaa6457fa034af, structured request e525bb7aba487577. Prior instruments archived after the advisor ruling on vocabulary leakage.
A4: Vendor switch | B4: Gemini archived after run 1; run 2 vendors are claude-sonnet-4-6 and gpt-5.6-terra. gpt-5.6-terra accepted temperature=0 in all three cells.
A5: Ceiling incident | B5: GPT unstructured exhausted the initial 8000-token cap via hidden reasoning tokens (8000 out, 1408 visible chars); re-run at 16000 completed at 1330. Original archived as ARCHIVED_plan_unstructured_astropy__astropy-12907_gpt-5.6-terra_run1_ceiling8000.json.
A6: Ceiling non-uniformity | B6: Claude cells ran under the 8000 cap and completed at 1164 / 7451 / 2453 output tokens; the cap is non-binding for completed generations, so values are comparable. All future runs use 16000.
A7: Parser incident | B7: The run-1 fence stripper misparsed responses whose JSON strings contain code fences. Mechanical parse fields of the four trajectory / structured artifacts were recomputed in place with the corrected parser (mechanical_fields_recomputed flag); response_text untouched. Record: artifact_parser_fix/notes.txt.
A8: Contamination: CLAUDE unstr | B8: names _cstack, _cdot
A9: Contamination: CLAUDE traj | B9: names _cstack, _cdot, _coord_matrix
A10: Contamination: CLAUDE struct | B10: names _cstack
A11: Contamination: GPT unstr | B11: names _cstack (re-run; archived truncated original did not reach it)
A12: Contamination: GPT traj | B12: names _cstack
A13: Contamination: GPT struct | B13: no repo-internal identifiers beyond the intent
A14: Contamination convention | B14: separable.py mentions are NOT contamination: derivable from the intent's own import line (locked run-1 ruling). _cstack and other internal names are disclosed as memorization.

Sheet Open_rulings
A1: Cells that need your ruling before this scorecard leaves DRAFT.
A3: # | B3: Ruling | C3: Evidence anchor
A4: 1 | B4: EF for trajectory cells | C4: RESOLVED: EF trajectory = 1.00 per run-1 precedent (every step carries a thought; narrowing stated). Recoverability rows 6 and 9 updated.
A5: 2 | B5: GT-04 CLAUDE trajectory | C5: RESOLVED CONFIRMED: GT-04 CT = 1 (coverage means named; fix named in step 32 thought and done summary; zero edit_file stays a recorded observation).
A6: 3 | B6: CLAUDE trajectory retry loop | C6: RESOLVED: precision stays scope-only; all 42 trajectory steps rel=1 (all target the issue's file and helpers); redundancy recorded as a mechanical ratio, 30/34 and 7/8, feeding the analysis-paralysis observation.
A7: 4 | B7: GT-01 GPT trajectory | C7: RESOLVED CONFIRMED: GT-01 GPT trajectory = 0.5 (failing-test-first names reproduction; disclosed divergence from run-1 precedent).
A8: 5 | B8: GT-01 CLAUDE structured | C8: RESOLVED CONFIRMED: GT-01 CLAUDE structured = 1 (monitor-as-reproduction: P1 captures the erroneous output).
A9: 6 | B9: SIF Resource CLAUDE structured | C9: RESOLVED CONFIRMED: 0.5 stands per the reassembly tier. Finding recorded: nested absent from P0.resource but present in five child resource fields (P1, P2.2, P3, P3.2, P5); the qualifier was refined downward, not lost.
A10: 7 | B10: SIF Context GPT structured | C10: RESOLVED CONFIRMED: GS context 0.5; root reads repository maintenance and no child carries production.
A11: 8 | B11: SIF prose cap | C11: RESOLVED CONFIRMED: the 0.5 prose cap carries over from the run-1 not-a-field convention.
A12: 9 | B12: GPT structured P8 | C12: RESOLVED OVERTURNED: P8 = 0 per run-1 ruling #3, the delivery/report class. GS precision 0.88.
A13: 10 | B13: Overhead timings | C13: RESOLVED: timings measured on the governing machine and entered (0.35 and 0.41 us traversal; O(n) baseline block added). Sheet Overhead.
A14: 11 | B14: Run-1 precision rulings carried | C14: RESOLVED: rulings #2 and #3 carried into run 2; carve-out added for reproduction-vehicle test authoring (rel 1). Precision row: 1.00 / 1.00 / 0.80 / 0.83 / 1.00 / 0.88.
A15: 12 | B15: Plan-stage precision re-ruling (meeting 2026-08-04) | C15: RESOLVED: beyond-intent-but-correct steps are not penalized; the LLM is the assurance engine and thorough refinement is its job. Supersedes run-1 rulings #2 and #3 and run-2 ruling #9. Four cells flipped to 1: Precision_struct C12 (P3.2), C14 (P5), H13 (P8); Precision_unstr H10 (U6). Precision is now 1.00 in all six cells. Anchors: 'you shouldn't penalize it'; 'report the updated result' (meeting transcript).
